Workbook

Sheet Tilgungsverlauf
D2: Tilgungsverlauf eines Darlehens
D4: Kreditsumme | G4: 210896 | N4: =IF($G$11=" F01 ","Tilgungsvariante fehlt",IF($G$11=" F 02 "," Zinstermin fehlt !!!",IF($G$11=" f 03 "," Kreditbetrag eintragen !!!",IF($G$11=" F 04 ","fehler 4",IF($G$11=" F 05 ","Fehler 5","")))))
D5: Zinssatz | G5: 3 | H5: (Jahreszins in %) / eff. Zins = | J5: =eff.zins -> 3.04
C6: Tilgungsart | D6: In Prozent | G6: 2.69 | H6: (jährliche Tilgungsrate in %)
C7: oder | D7: Fester Betrag (incl. Zinsen) | G7: 950 | H7: (gewünschter Betrag je Zahlungstermin)
C8: oder | D8: Anzahl Raten | G8: 359 | H8: (Anzahl der gewünschten Raten)
D9: Zahlungsweise | G9: M | H9: (M=monatlich, Q=quartlisch, H=halbjährlich J=jährlich)
D10: Zahlungsbeginn | G10: 43830
D11: =IF($G$7=Hitab!$G$11,"",IF(G9="m"," mtl. Betrag",IF(G9="Q"," quartl. Betrag",IF(G9="H"," halbjährl. Betrag"," jährl. Betrag")))) -> mtl. Betrag | G11: =IF($G$7=Hitab!$G$11," ",Hitab!G11) -> 999.99853 | H11: =IF($G$7=Hitab!$G$11,"", " EUR") -> EUR | I11: =IFERROR(VLOOKUP(periodische_Zahlung,Hitab!O3:P7,2,FALSE()),"")
D12: =IF($G$8=Hitab!$G$12,"","Anz. Raten") -> Anz. Raten | G12: =IF(Anz.Raten>480,"Tilgung zu gering",Hitab!G12) -> 301 | I12: ohne Sondertilgung | M12: Tilgungsverlauf anzeigen? | N12: J
G13: =IFERROR(IF($H$7797=Hitab!$G$12,"",IF(ISNUMBER(INDEX(G:G,MATCH(MAX($F$18:$F$31),$F:$F))),"",MATCH(MAX($F$18:$F$31),$F:$F,0)-18)),"") -> 13 | I13: =IF(AND(ISNUMBER(G13),G12<>G13),"mit Sondertilgung","") -> mit Sondertilgung
D14: Letzte Rate | G14: =IF(AND(MAX($F$19:$F$31)>G10,ISNUMBER(G13)),MAX($F$19:$F$31),letzte_Zahlung) -> 52962 | I14: unter Berücksichtung der Sondertilgungen | L14: =IF(Tilgungsverlauf_rechnen="J",LARGE(L18:L999,1),N14-G4) -> 75680.949 | M14: =N14-L14 -> 116318.77 | N14: =IF(Tilgungsverlauf_rechnen="J",LARGE(N18:N999,1),Hitab!G13) -> 191999.72 | Q14: =IF(SUM(Q18:Q31)>0,SUM(Q18:Q31),"")
E17: Zeitverlauf | F17: =IF($G$10<>"","Zahlungstermine","") -> Zahlungstermine | G17: Kredit | H17: Zinsen | I17: Tilgung | J17: Zahlung | L17: Ʃ Zinsen | M17: Ʃ Tilgung | N17: Ʃ Zahlungen | Q17: Sondertilgung
G18: =IF(Tilgungsverlauf_rechnen="J",SUM(G4)," ") -> 210896
B19: =zeige.Jahr -> 0 | C19: =zeige.Jahrtxt | D19: =zeige.Monat -> 1 | E19: =zeige.Monattxt -> Monat | F19: =rechne.Zahlungstermine -> 43830 | G19: =rechne.Restkredit -> 210423.24 | H19: =rechne.Zinsen -> 527.24 | I19: =rechne.Tilgung -> 472.75853 | J19: =rechne.Betrag -> 999.99853 | L19: =rechne.GesZins -> 527.24 | M19: =rechne.GesTilg -> 472.75853 | N19: =rechne.GesAufwand -> 999.99853 | P19: =rechne.AnzMonate
B20: =zeige.Jahr -> 0 | C20: =zeige.Jahrtxt | D20: =zeige.Monat -> 2 | E20: =zeige.Monattxt -> Monate | F20: =rechne.Zahlungstermine -> 43861 | G20: =rechne.Restkredit | H20: =rechne.Zinsen | I20: =rechne.Tilgung | J20: =rechne.Betrag -> 999.99853 | L20: =rechne.GesZins | M20: =rechne.GesTilg | N20: =rechne.GesAufwand -> 0 | P20: =rechne.AnzMonate
B21: =zeige.Jahr -> 0 | C21: =zeige.Jahrtxt | D21: =zeige.Monat -> 3 | E21: =zeige.Monattxt -> Monate | F21: =rechne.Zahlungstermine -> 43890 | G21: =rechne.Restkredit | H21: =rechne.Zinsen | I21: =rechne.Tilgung | J21: =rechne.Betrag | L21: =rechne.GesZins | M21: =rechne.GesTilg | N21: =rechne.GesAufwand | P21: =rechne.AnzMonate
B22: =zeige.Jahr -> 0 | C22: =zeige.Jahrtxt | D22: =zeige.Monat -> 4 | E22: =zeige.Monattxt -> Monate | F22: =rechne.Zahlungstermine -> 43921 | G22: =rechne.Restkredit | H22: =rechne.Zinsen | I22: =rechne.Tilgung | J22: =rechne.Betrag | L22: =rechne.GesZins | M22: =rechne.GesTilg | N22: =rechne.GesAufwand | P22: =rechne.AnzMonate
B23: =zeige.Jahr -> 0 | C23: =zeige.Jahrtxt | D23: =zeige.Monat -> 5 | E23: =zeige.Monattxt -> Monate | F23: =rechne.Zahlungstermine -> 43951 | G23: =rechne.Restkredit -> 208520.36 | H23: =rechne.Zinsen | I23: =rechne.Tilgung | J23: =rechne.Betrag | L23: =rechne.GesZins | M23: =rechne.GesTilg | N23: =rechne.GesAufwand | P23: =rechne.AnzMonate
B24: =zeige.Jahr -> 0 | C24: =zeige.Jahrtxt | D24: =zeige.Monat -> 6 | E24: =zeige.Monattxt -> Monate | F24: =rechne.Zahlungstermine -> 43982 | G24: =rechne.Restkredit | H24: =rechne.Zinsen | I24: =rechne.Tilgung | J24: =rechne.Betrag | L24: =rechne.GesZins | M24: =rechne.GesTilg | N24: =rechne.GesAufwand | P24: =rechne.AnzMonate
B25: =zeige.Jahr -> 0 | C25: =zeige.Jahrtxt | D25: =zeige.Monat -> 7 | E25: =zeige.Monattxt -> Monate | F25: =rechne.Zahlungstermine -> 44012 | G25: =rechne.Restkredit | H25: =rechne.Zinsen | I25: =rechne.Tilgung | J25: =rechne.Betrag | L25: =rechne.GesZins | M25: =rechne.GesTilg | N25: =rechne.GesAufwand | P25: =rechne.AnzMonate
B26: =zeige.Jahr -> 0 | C26: =zeige.Jahrtxt | D26: =zeige.Monat -> 8 | E26: =zeige.Monattxt -> Monate | F26: =rechne.Zahlungstermine -> 44043 | G26: =rechne.Restkredit | H26: =rechne.Zinsen | I26: =rechne.Tilgung | J26: =rechne.Betrag | L26: =rechne.GesZins | M26: =rechne.GesTilg | N26: =rechne.GesAufwand | P26: =rechne.AnzMonate
B27: =zeige.Jahr -> 0 | C27: =zeige.Jahrtxt | D27: =zeige.Monat -> 9 | E27: =zeige.Monattxt -> Monate | F27: =rechne.Zahlungstermine -> 44074 | G27: =rechne.Restkredit | H27: =rechne.Zinsen | I27: =rechne.Tilgung | J27: =rechne.Betrag | L27: =rechne.GesZins | M27: =rechne.GesTilg | N27: =rechne.GesAufwand | P27: =rechne.AnzMonate
B28: =zeige.Jahr -> 0 | C28: =zeige.Jahrtxt | D28: =zeige.Monat -> 10 | E28: =zeige.Monattxt -> Monate | F28: =rechne.Zahlungstermine -> 44104 | G28: =rechne.Restkredit | H28: =rechne.Zinsen | I28: =rechne.Tilgung | J28: =rechne.Betrag | L28: =rechne.GesZins | M28: =rechne.GesTilg | N28: =rechne.GesAufwand | P28: =rechne.AnzMonate
B29: =zeige.Jahr -> 0 | C29: =zeige.Jahrtxt | D29: =zeige.Monat -> 11 | E29: =zeige.Monattxt -> Monate | F29: =rechne.Zahlungstermine -> 44135 | G29: =rechne.Restkredit | H29: =rechne.Zinsen | I29: =rechne.Tilgung | J29: =rechne.Betrag | L29: =rechne.GesZins | M29: =rechne.GesTilg | N29: =rechne.GesAufwand | P29: =rechne.AnzMonate
B30: =zeige.Jahr -> 1 | C30: =zeige.Jahrtxt -> Jahr | D30: =zeige.Monat -> 0 | E30: =zeige.Monattxt | F30: =rechne.Zahlungstermine -> 44165 | G30: =rechne.Restkredit -> 205144.24 | H30: =rechne.Zinsen | I30: =rechne.Tilgung | J30: =rechne.Betrag | L30: =rechne.GesZins | M30: =rechne.GesTilg | N30: =rechne.GesAufwand | P30: =rechne.AnzMonate
... B210: =zeige.Jahr -> 16 | C210: =zeige.Jahrtxt -> Jahre | D210: =zeige.Monat -> 0 | E210: =zeige.Monattxt | F210: =rechne.Zahlungstermine -> 49643 | G210: =rechne.Restkredit | H210: =rechne.Zinsen | I210: =rechne.Tilgung | J210: =rechne.Betrag | L210: =rechne.GesZins | M210: =rechne.GesTilg | N210: =rechne.GesAufwand | P210: =rechne.AnzMonate

Sheet Infos
B1: Berechnung des effektiven Jahreszins nach der Uniform-Methode
B3: Die einfachste Art zur Berechnung des ungefähren effektiven Jahreszinses ist die Uniform-Methode:
B7: Kreditkosten = (gesamte Rückzahlung − Auszahlungsbetrag) oder (Anzahl der Raten × Ratenbetrag − Auszahlungsbetrag)
B9: dazu gehören:
B11: Bearbeitungsgebühr
B12: Zinsen
B13: evtl. Restschuldversicherung bzw. Kreditlebensversicherung (sofern verpflichtend im Angebot enthalten [7])
B15: Nettodarlehensbetrag = Darlehensnennbetrag − Kreditkosten
B17: Anwendungsbereich
B19: Die Uniform-Methode ermöglicht bei bestimmten Darlehensarten eine Abschätzung des Effektivzinssatzes. Rechtlich gültig und von Finanzdienstleistern auszuweisen ist die komplizierter zu berechnende, aber genauere Effektivverzinsung nach PAngV. Die Uniform-Methode ist als überschlägige Berechnung anzusehen, mit der man insbesondere bei mit gleichen Monatsraten zu tilgenden Krediten schnell einen Eindruck von dem zu erwartenden tatsächlichen Effektivzins erhalten kann. Das Ergebnis kann von der PAngV-Effektivverzinsung abweichen.
B21: Beispiel
B23: Ein Verbraucherkredit über 10.000,00 EUR wird aufgenommen. Der Zinssatz beträgt 0,5 % pro Monat und bezieht sich während der gesamten Laufzeit auf die Ursprungssumme von 10.000,00 EUR, die Laufzeit liegt bei 60 Monaten. Zur Bereitstellung werden 3 % Bearbeitungsgebühr erhoben. Die Bearbeitungsgebühr wird bei Kreditaufnahme entrichtet, bereitgestellt werden die vollen 10.000,00 EUR.
B29: Anm.: Zinsen und Tilgung werden monatlich gezahlt, aber der Kreditbetrag gilt erst am Ende der Laufzeit als komplett getilgt, d. h. monatlich wird eine Rate von
N30: =((3300/10000)*(24/(60+1)*100)) -> 12.983607 | O30: =((3000/10000)*(24/(60+1)*100)) -> 11.803279
B31: fällig.
N32: =EFFECT(0.0197,12)*100 -> 1.9878852
B34: Der eff. Zinssatz (Jahreszinssatz) errechnet sich durch die Zinsung aller Einnahmen und Ausgaben auf einen Zinszeitpunkt mit dem Ergebnis „Null“. Dann entsprechen sich gezinst alle Einnahmen und Ausgaben.
B36: Unter Annahme der Auszahlung in Höhe von 10.000€ und der Gebühr in Höhe 300€ zum Auszahlungszeitpunkt sowie 60 Monatsraten in Höhe von 221,67€ beginnend mit dem Auszahlungszeitpunkt ergibt sich ein eff. Zinssatz von 14,5950 %. Sofern die Ratenzahlungen einen Monat später beginnen, ist der eff. Zinssatz 14,0221 %. Der jeweils zu ermittelnde gezinste Betrag wird wie folgt errechnet: Betrag x (1 + Zinssatz) ^ „Zeit in Jahren“, wobei „Zeit in Jahren“ ein Teilwert sein kann und auch ein negativer Wert.
B38: Berechnung des eff. Jahreszinssatzes bei Anleihen
B40: Den effektiven Jahreszinssatz bei endfälligen Anleihen, die über mehrere Jahre laufen und den Zins wieder mitverzinsen (Zinseszins), berechnet man mit Zinsfaktoren:
B44: Bsp.: Eine Anleihe läuft 3 Jahre und wird mit 1,5 % im ersten, 2 % im zweiten und 3 % im dritten Jahr verzinst.
B53: Bei Anleihen wird oft mit der Näherungsformel mit Auf- (Agio) und Abschlägen (Disagio) gerechnet:
B57: (Diese Formel weicht bei kleinen Werten für Laufzeit und Agio/Disagio kaum vom korrekten Ergebnis ab, versagt aber bei entsprechend großen Werten.)
B59: Allerdings handelt es sich bei dem Faktor
B60: lediglich um einen weiteren Zinsfaktor, mit dem dann eine präzisere Formel konstruiert werden kann:
B64: Berechnung des eff. Jahreszinssatzes bei Krediten mit festen monatlichen Raten
B66: Die folgende Berechnungsvorschrift wird für Kredite hergeleitet, für die weder einmalige Zuschläge (Bearbeitungsgebühren) noch Abschläge (Disagio) vereinbart sind.
B68: Der von der Bank üblicherweise angegebene Zinssatz ist eigentlich überhaupt kein Jahreszinssatz, sondern das Zwölffache eines „effektiven Monatszinssatzes“. Nach jedem Monat – bzw. nach jedem Zwölftel des Jahres – wird folglich saldiert und neu gerechnet. Der Zinseszinseffekt tritt also bereits nach dem ersten Monat auf, und dies führt dazu, dass unter den für diesen Abschnitt genannten Bedingungen der effektive Jahreszinssatz immer höher ist als der von der Bank genannte Zinssatz.
B70: Zur Herleitung der Berechnungsvorschrift stellen wir die Bildung der monatlichen bzw. jahresendlichen Kontobeträge für monatliche und jahresendliche Saldierung einander gegenüber. Folgende Größen spielen dabei eine Rolle:
B72: G0 | C72: = | D72: Schuld zu Beginn des Jahres
B73: R | C73: = | D73: monatliche Rate, die Zins und u.U. auch Tilgung enthält
B74: z | C74: = | D74: Bankzinssatz
B75: zeff | C75: = | D75: effektiver Jahreszinssatz
B77: Für den von der Bank genannten Zinssatz gilt nach i Monaten:
B88: Für den effektiven Jahreszinssatz gilt nach einem Jahr (in Gegenüberstellung zu obiger Formel für i = 12):
B92: Der Subtrahend ergibt sich zum einen aus den Raten, die innerhalb des Jahres keine Zinszahlungen enthalten - da ein effektiver Jahreszinssatz nur am Jahresende angewendet wird -, und aus der Verzinsung dieser vor dem Jahresende geleisteten Raten bis zum Ende des Jahres: Die erste liegt elf Monate an, die zweite zehn usw. und die letzte wird genau zum Jahresende geleistet und erzielt deshalb keine Verzinsung. Diese Verzinsung muss dem Tilgenden ebenfalls gutgeschrieben werden.
B94: Gleichsetzung beider Formeln für G12 und Austausch von R durch x G0 liefert schließlich für zeff folgende Formel:
B98: Die Berechnung des effektiven Jahreszinssatzes ist also nicht nur vom Bankzinssatz, sondern auch von der Geschwindigkeit der Tilgung abhängig, also vom Verhältnis zwischen R und G0. Stark vereinfacht wird die Formel, wenn keine Tilgung erfolgt, sondern die Raten nur die fälligen Zinsen begleichen. Dann wird x = z / 12, und daraus folgt:
B102: Diese Formel mag unglaubwürdig erscheinen, weil sie für z = 24 / 11 nicht definiert ist und für noch höhere Werte z sogar unsinnige negative Ergebnisse liefert. Man muss sich jedoch klarmachen, was es heißt, einen Bankzinssatz von 218 % präsentiert zu bekommen. Innerhalb von sechs Monaten wird über die monatlichen Beträge eine größere Summe gezahlt, als die Schuldsumme vom Jahresanfang ausmacht. Nach der Vorgehensweise des effektiven Jahreszinssatzes bedeutet dies, dass der Schuldner, der ja während des Jahres keine Zinsen zahlt, sondern nur tilgt, ab dem sechsten Monat ein Guthaben bei der Bank bildet. Dieses Guthaben muss die Bank natürlich ebenso verzinsen wie zuvor die Schuld – nur mit umgekehrtem Vorzeichen. Beide Zinsen werden gegeneinander aufgerechnet und müssen ohne jegliche Tilgung den Wert null ergeben. Das kann aber nicht funktionieren, wenn die Schuldsumme vom Jahresanfang bereits vor der Jahreshälfte getilgt worden ist. Folglich müssen die Zinsen auf die im Laufe statt am Ende des Jahres gezahlten Raten den Ausschlag geben. Und dazu müssen sie eben sehr hoch sein - im Extremfall unendlich.
B104: Für Zinssätze in normalen Größenordnungen liefert die Formel jedoch nicht nur (ebenfalls) korrekte, sondern zudem einleuchtende Ergebnisse. Wird eine Schuldsumme von 100 Euro innerhalb eines Jahres getilgt, wobei ein Bankzinssatz von 10 % angesetzt wird, so ergibt sich der effektive Jahreszinssatz zu 10,65 %. Soll die Schuld bei gleichem Bankzinssatz nur gehalten werden, so beläuft sich der effektive Jahreszinssatz auf 10,48 %
...

Sheet Hitab
J1: J | K1: M | L1: 12 | M1: 1 | O1: Fehlermeldungen
J2: N | K2: Q | L2: 4 | M2: 3 | O2: Nr. | P2: Text
B3: =IF(Zahlweise="M",12,IF(Zahlweise="Q",4,IF(Zahlweise="H",2,1))) -> 12 | C3: = Divisor für Zinssatz | K3: H | L3: 2 | M3: 6 | O3: F01 | P3: Tilgungsvariante fehlt
B4: =ROUND(NPER($G$5%/Divisor,G11,G4*-1),15) -> 300.04205 | C4: = Anzahl Zahlungsperioden | F4: Kredit | G4: =Kreditbetrag -> 210896 | K4: J | L4: 1 | M4: 12 | O4: F 02 | P4: Zahlungsperiode fehlt !!!
B5: =IF(Divisor=12,1,IF(Divisor=4,3,IF(Divisor=2,6,12))) -> 1 | C5: = Additionswert für Anzahl Monate | F5: Zins | G5: =IF(AND(C8>0,C13=0),C8,IF(AND(C8=0,C13>0),C13,)) -> 3 | O5: F 03 | P5: Kreditbetrag eintragen !!!
B6: =ROUNDUP(Anzahl_Z_Perioden,0) -> 301 | C6: = Anz.Zahlungen aufgerundet | F6: Tilgung | G6: =C9 -> 2.69 | O6: F 04 | P6: fehler 4
B7: =Kreditbetrag -> 210896 | D7: Kreditsumme | F7: Zahlung | G7: =C10 -> 0 | O7: F 05 | P7: Fehler 5
B8: =Zinssatz_in_Prozent -> 3 | C8: =IF(AND(ISNUMBER($B$8),$B$8>0),$B$8,IF(AND(ISNUMBER($C$11),$C$11>0,ISNUMBER($C$10),$C$10>0,ISNUMBER($G$4),$G$4>0),SUM(RATE($C$11,-$C$10,$G$4)*$B$3*100),0)) -> 3 | D8: Zinssatz | F8: Anzahl Raten | G8: =C11 -> 0
B9: =Tilgung_in_Prozent -> 2.69 | C9: =IF(AND(ISNUMBER(B9),B9>0),B9,0) -> 2.69 | D9: Zinssatz Tilgung | F9: Zinstermin | G9: =Tilgungsverlauf!G9 -> M
B10: =Tilgung_in_DM -> 950 | C10: =IF(AND(C9=0,B10>0),B10,0) -> 0 | D10: Zahlbetrag je Periode | F10: Zahlungsbeginn | G10: =Tilgungsverlauf!G10 -> 43830 | I10: Letzte Zahlung | K10: =EDATE(G10,(B6*VLOOKUP(G9,K1:M4,3,FALSE())-1)) -> 52962
B11: =Tilgung_in_Anzahl_Perioden -> 359 | C11: =IF(AND($C$9=0,$C$10=0,$B$11>0),$B$11,0) -> 0 | D11: Anzahl Raten | F11: Zahlung | G11: =IF(AND(ISNUMBER(G4),G4<>0),IF(OR($G$9="J",$G$9="H",$G$9="Q",$G$9="M"),IF(AND(ISNUMBER($G$6),$G$6>0),$G$4/100*($G$5+$G$6)/Divisor,IF(AND(ISNUMBER($G$7),$G$7>0),$G$7,IF(AND(ISNUMBER($G$8),$G$8>0),PMT($G$5%/Divisor,IF($G$8>0,$G$8,1),$G$4*-1)," F 01 ")))," F 02 ")," F 03 ") -> 999.99853
C12: =IF(AND($C$8=0,$C$9=0,$B$11>0,C11=0),$B$11,0) -> 0 | F12: Anzahl Raten | G12: =IF(ISNUMBER(Anzahl_Z_Perioden),INT(SUM(Anzahl_Z_Perioden,0.99999))," ") -> 301
C13: =IF(AND($C$8=0,C11=0,C12>0),SUM(RATE($C$12,-$C$10,$G$4)*$B$3*100),0) -> 0 | F13: Gesamtsumme | G13: =Anzahl_Z_Perioden*G11 -> 300041.61 | I13: Ges. aus Tilgungsverlauf: | K13: =IFERROR(LARGE(Tilgungsverlauf!N17:N8908,1),"") -> 191999.72
F15: eff. Zins | G15: =ROUND(EFFECT(G5/100,VLOOKUP(G9,K1:L4,2,FALSE()))*100,2) -> 3.04
